Workbook

Sheet Dashboard
A1: Academic Success Plan — Dashboard
A2: Bugün: | B2: =TODAY() | D2: Tamamlanma ≠ öğrenme seviyesi. Öğrenme için Topic Mastery'yi doldur.
A4: Toplam görev | B4: Tamamlanan | C4: % Tamamlanma | D4: % Min plan | E4: Planlanan saat | F4: Tamamlanan saat | G4: Geciken görev
A5: ='Course Progress'!B11 -> 431 | B5: ='Course Progress'!C11 -> 0 | C5: ='Course Progress'!D11 -> 0 | D5: ='Course Progress'!G11 -> 0 | E5: ='Course Progress'!H11/60 -> 259.52 | F5: ='Course Progress'!I11/60 -> 0 | G5: ='Course Progress'!J11
A7: Ders bazlı ilerleme
A8: Ders | B8: Ad | C8: % Tamamlanma | D8: % Min plan | E8: Tamamlanan / Toplam | F8: Geciken | G8: Ort. öğrenme skoru
A9: BIO110 | B9: Introduction to Modern Biology | C9: ='Course Progress'!D5 -> 0 | D9: ='Course Progress'!G5 -> 0 | E9: ='Course Progress'!C5&" / "&'Course Progress'!B5 -> 0 / 92 | F9: ='Course Progress'!J5 | G9: =IFERROR(AVERAGEIFS('Topic Mastery'!$E$5:$E$87,'Topic Mastery'!$A$5:$A$87,A9),"—") -> —
A10: CMPE371 | B10: Signals and Systems | C10: ='Course Progress'!D6 -> 0 | D10: ='Course Progress'!G6 -> 0 | E10: ='Course Progress'!C6&" / "&'Course Progress'!B6 -> 0 / 85 | F10: ='Course Progress'!J6 | G10: =IFERROR(AVERAGEIFS('Topic Mastery'!$E$5:$E$87,'Topic Mastery'!$A$5:$A$87,A10),"—") -> —
A11: CMPE327 | B11: Automata / Theory of Computation | C11: ='Course Progress'!D7 -> 0 | D11: ='Course Progress'!G7 -> 0 | E11: ='Course Progress'!C7&" / "&'Course Progress'!B7 -> 0 / 91 | F11: ='Course Progress'!J7 | G11: =IFERROR(AVERAGEIFS('Topic Mastery'!$E$5:$E$87,'Topic Mastery'!$A$5:$A$87,A11),"—") -> —
A12: CMPE421 | B12: Artificial Intelligence | C12: ='Course Progress'!D8 -> 0 | D12: ='Course Progress'!G8 -> 0 | E12: ='Course Progress'!C8&" / "&'Course Progress'!B8 -> 0 / 77 | F12: ='Course Progress'!J8 | G12: =IFERROR(AVERAGEIFS('Topic Mastery'!$E$5:$E$87,'Topic Mastery'!$A$5:$A$87,A12),"—") -> —
A13: CMPE453 | B13: Microprocessors (ATmega328P / STM32) | C13: ='Course Progress'!D9 -> 0 | D13: ='Course Progress'!G9 -> 0 | E13: ='Course Progress'!C9&" / "&'Course Progress'!B9 -> 0 / 68 | F13: ='Course Progress'!J9 | G13: =IFERROR(AVERAGEIFS('Topic Mastery'!$E$5:$E$87,'Topic Mastery'!$A$5:$A$87,A13),"—") -> —
A14: CMPE499 | B14: Summer Training (rapor + video) | C14: ='Course Progress'!D10 -> 0 | D14: ='Course Progress'!G10 -> 0 | E14: ='Course Progress'!C10&" / "&'Course Progress'!B10 -> 0 / 18 | F14: ='Course Progress'!J10 | G14: =IFERROR(AVERAGEIFS('Topic Mastery'!$E$5:$E$87,'Topic Mastery'!$A$5:$A$87,A14),"—") -> —
A16: Yaklaşan sınav / teslim (Exam Countdown'dan)
A17: Ders | B17: Başlık | C17: Tarih | D17: Gün kaldı | E17: Durum
A18: ='Exam Countdown'!A5 -> BIO110 | B18: ='Exam Countdown'!B5 -> BIO110 Midterm 1 | C18: =IF('Exam Countdown'!C5="","",'Exam Countdown'!C5) -> 46329 | D18: ='Exam Countdown'!G5 | E18: ='Exam Countdown'!F5 -> Kullanıcı teyitli
A19: ='Exam Countdown'!A6 -> CMPE371 | B19: ='Exam Countdown'!B6 -> CMPE371 HW1 (2–6 Kas haftası) | C19: =IF('Exam Countdown'!C6="","",'Exam Countdown'!C6) -> 46332 | D19: ='Exam Countdown'!G6 | E19: ='Exam Countdown'!F6 -> Teyit Bekliyor
A20: ='Exam Countdown'!A7 -> CMPE453 | B20: ='Exam Countdown'!B7 -> CMPE453 Midterm | C20: =IF('Exam Countdown'!C7="","",'Exam Countdown'!C7) -> 46338 | D20: ='Exam Countdown'!G7 | E20: ='Exam Countdown'!F7 -> Kesin (syllabus)
A21: ='Exam Countdown'!A8 -> CMPE327 | B21: ='Exam Countdown'!B8 -> CMPE327 Midterm (15 Kasım) | C21: =IF('Exam Countdown'!C8="","",'Exam Countdown'!C8) -> 46341 | D21: ='Exam Countdown'!G8 | E21: ='Exam Countdown'!F8 -> Kullanıcı teyitli
A22: ='Exam Countdown'!A9 -> CMPE421 | B22: ='Exam Countdown'!B9 -> CMPE421 Midterm (20 Kasım) | C22: =IF('Exam Countdown'!C9="","",'Exam Countdown'!C9) -> 46346 | D22: ='Exam Countdown'!G9 | E22: ='Exam Countdown'!F9 -> Kullanıcı teyitli
A23: ='Exam Countdown'!A10 -> CMPE499 | B23: ='Exam Countdown'!B10 -> CMPE499 Summer Training Report (STR) | C23: =IF('Exam Countdown'!C10="","",'Exam Countdown'!C10) -> 46348 | D23: ='Exam Countdown'!G10 | E23: ='Exam Countdown'!F10 -> Kesin (syllabus)
A24: ='Exam Countdown'!A11 -> CMPE371 | B24: ='Exam Countdown'!B11 -> CMPE371 Midterm (23–27 Kas haftası) | C24: =IF('Exam Countdown'!C11="","",'Exam Countdown'!C11) -> 46349 | D24: ='Exam Countdown'!G11 | E24: ='Exam Countdown'!F11 -> Teyit Bekliyor
A25: ='Exam Countdown'!A12 -> BIO110 | B25: ='Exam Countdown'!B12 -> BIO110 Midterm 2 (26/27 Kas) | C25: =IF('Exam Countdown'!C12="","",'Exam Countdown'!C12) -> 46352 | D25: ='Exam Countdown'!G12 | E25: ='Exam Countdown'!F12 -> Teyit Bekliyor
A26: ='Exam Countdown'!A13 -> CMPE499 | B26: ='Exam Countdown'!B13 -> CMPE499 Summer Training Video | C26: =IF('Exam Countdown'!C13="","",'Exam Countdown'!C13) -> 46355 | D26: ='Exam Countdown'!G13 | E26: ='Exam Countdown'!F13 -> Kesin (syllabus)
A27: ='Exam Countdown'!A14 -> CMPE371 | B27: ='Exam Countdown'!B14 -> CMPE371 Quiz 1 (7–11 Ara haftası) | C27: =IF('Exam Countdown'!C14="","",'Exam Countdown'!C14) -> 46363 | D27: ='Exam Countdown'!G14 | E27: ='Exam Countdown'!F14 -> Teyit Bekliyor
A28: ='Exam Countdown'!A15 -> BIO110 | B28: ='Exam Countdown'!B15 -> BIO110 Proje sunumları (10–31 Ara) | C28: =IF('Exam Countdown'!C15="","",'Exam Countdown'!C15) -> 46366 | D28: ='Exam Countdown'!G15 | E28: ='Exam Countdown'!F15 -> Teyit Bekliyor (aralık)
A29: ='Exam Countdown'!A16 -> CMPE327 | B29: ='Exam Countdown'!B16 -> CMPE327 Quiz-2 (14–18 Ara haftası) | C29: =IF('Exam Countdown'!C16="","",'Exam Countdown'!C16) -> 46370 | D29: ='Exam Countdown'!G16 | E29: ='Exam Countdown'!F16 -> Teyit Bekliyor
A30: ='Exam Countdown'!A17 -> GENEL | B30: ='Exam Countdown'!B17 -> Final sınavları (W14 sonrası) | C30: =IF('Exam Countdown'!C17="","",'Exam Countdown'!C17) | D30: ='Exam Countdown'!G17 | E30: ='Exam Countdown'!F17 -> Duyurulacak

Sheet Daily Tasks
A1: ID | B1: Tarih | C1: Gün | D1: Ders | E1: Seviye | F1: Öncelik | G1: Süre (dk) | H1: Görev | I1: Materyal / Slayt | J1: Durum | K1: Not | L1: Kritik
A2: 2026-10-30-01 | B2: 46325 | C2: Cuma | D2: GENEL | E2: Min | F2: P1 | G2: 25 | H2: Doğrulama paketi — (1) BIO110 midterm 1 kapsamı (hangi bölümler); (2) CMPE327 (15 Kas) ve CMPE421 (20 Kas) vize kapsamları; (3) CMPE453 vize kapsamı; (4) CMPE371 HW1 teslim günü; (5) CMPE327 Quiz-1 (syllabus W5) yapıldı mı. ▸ Sonuçları Exam Countdown sayfasına/plana not et; tarih değişirse REPLAN_GUIDE'a göre güncelle | J2: Not Started
A3: 2026-10-30-02 | B3: 46325 | C3: Cuma | D3: BIO110 | E3: Min | F3: P1 | G3: 75 | H3: The Chemical Context of Life — atom, element, izotop, elektron kabukları, kovalent/iyonik/hidrojen bağı, kimyasal reaksiyon ve denge. ▸ 15 kavram sorusu + 10 flashcard (bağ türleri tablosu) | I3: Campbell Biology (ilgili bölüm; baskıya göre numara değişir) + hoca slaytı — Materyal bekleniyor | J3: Not Started
A4: 2026-10-30-03 | B4: 46325 | C4: Cuma | D4: BIO110 | E4: Min | F4: P1 | G4: 70 | H4: Water and Life — suyun polaritesi, H-bağı, kohezyon/adezyon, özgül ısı, çözücülük, pH ve tampon. ▸ 15 kavram sorusu + özellik→örnek tablosu + 10 flashcard | I4: Campbell Biology (ilgili bölüm; baskıya göre numara değişir) + hoca slaytı — Materyal bekleniyor | J4: Not Started
A5: 2026-10-30-04 | B5: 46325 | C5: Cuma | D5: BIO110 | E5: Min | F5: P1 | G5: 60 | H5: Carbon and Molecular Diversity — karbon iskeleti, hidrokarbonlar, izomer türleri, 7 fonksiyonel grup. ▸ Fonksiyonel grup kartları (7) + 12 izomer/grup sorusu | I5: Campbell Biology (ilgili bölüm; baskıya göre numara değişir) + hoca slaytı — Materyal bekleniyor | J5: Not Started
A6: 2026-10-30-05 | B6: 46325 | C6: Cuma | D6: CMPE371 | E6: Min | F6: P2 | G6: 40 | H6: Önkoşul: karmaşık sayılar ve Euler — a+jb, kutupsal gösterim, |z|, ∠z, e^{jθ}=cosθ+j sinθ, çarpma/bölme. ▸ 8 temel problem (kutupsal↔kartezyen) | I6: Hoca slaytı + ders kitabı (syllabus'ta belirtilmemiş: Materyal bekleniyor) — Materyal bekleniyor | J6: Not Started
A7: 2026-10-30-06 | B7: 46325 | C7: Cuma | D7: BIO110 | E7: Ext | F7: P1 | G7: 25 | H7: Hızlı hatırlama — B01–B02 kartları. ▸ 20 soru kapalı kitap | I7: Campbell Biology (ilgili bölüm; baskıya göre numara değişir) + hoca slaytı — Materyal bekleniyor | J7: Not Started
A8: 2026-10-30-07 | B8: 46325 | C8: Cuma | D8: CMPE327 | E8: Ext | F8: P3 | G8: 80 | H8: Central concepts + mathematical preliminaries — alfabe, string, dil, işlemler; küme, ilişki, fonksiyon; tümevarım ve çelişki ile ispat. ▸ 6 dil tanımlama + 2 tümevarım ispatı | I8: Hoca slaytı + ders kitabı (syllabus'ta belirtilmemiş: Materyal bekleniyor) — Materyal bekleniyor | J8: Not Started
A9: 2026-10-31-01 | B9: 46326 | C9: Cumartesi | D9: BIO110 | E9: Min | F9: P1 | G9: 70 | H9: Büyük moleküller I: karbonhidrat + lipid — monomer/polimer, dehidrasyon-hidroliz, glikozidik bağ, nişasta/glikojen/selüloz, yağ asidi, fosfolipid. ▸ Karşılaştırma tablosu + 15 soru | I9: Campbell Biology (ilgili bölüm; baskıya göre numara değişir) + hoca slaytı — Materyal bekleniyor | J9: Not Started
A10: 2026-10-31-02 | B10: 46326 | C10: Cumartesi | D10: BIO110 | E10: Min | F10: P1 | G10: 80 | H10: Büyük moleküller II: protein + nükleik asit — amino asit, peptit bağı, 4 yapı düzeyi, denatürasyon, DNA/RNA yapısı. ▸ Protein yapı basamaklarını belleğten çiz + 15 soru | I10: Campbell Biology (ilgili bölüm; baskıya göre numara değişir) + hoca slaytı — Materyal bekleniyor | J10: Not Started
A11: 2026-10-31-03 | B11: 46326 | C11: Cumartesi | D11: BIO110 | E11: Min | F11: P1 | G11: 70 | H11: Hücre turu I — prokaryot/ökaryot, çekirdek, ribozom, endomembran sistemi (ER, Golgi, lizozom, vakuol). ▸ Hücre şemasını boş çizip etiketle + 15 soru | I11: Campbell Biology (ilgili bölüm; baskıya göre numara değişir) + hoca slaytı — Materyal bekleniyor | J11: Not Started
A12: 2026-10-31-04 | B12: 46326 | C12: Cumartesi | D12: CMPE371 | E12: Ext | F12: P2 | G12: 50 | H12: Önkoşul: trigonometri, üstel, türev/integral — sin/cos özdeşlikleri, e^x kuralları, temel türev ve belirli integral. ▸ 10 problem | I12: Hoca slaytı + ders kitabı (syllabus'ta belirtilmemiş: Materyal bekleniyor) — Materyal bekleniyor | J12: Not Started
A13: 2026-10-31-05 | B13: 46326 | C13: Cumartesi | D13: CMPE327 | E13: Ext | F13: P3 | G13: 80 | H13: DFA — tanım (5'li), geçiş tablosu/diyagramı, dil tanıma, tasarım. ▸ 8 DFA çiz (son iki sembol, mod sayma, alt dize) | I13: Hoca slaytı + ders kitabı (syllabus'ta belirtilmemiş: Materyal bekleniyor) — Materyal bekleniyor | J13: Not Started
A14: 2026-10-31-06 | B14: 46326 | C14: Cumartesi | D14: CMPE327 | E14: Min | F14: P3 | G14: 8 | H14: Tekrar (kapalı kitap aktif hatırlama, konu başına ~8 dk): Central concepts + mathematical preliminaries (D+1) | J14: Not Started
A15: 2026-10-31-07 | B15: 46326 | C15: Cumartesi | D15: BIO110 | E15: Min | F15: P2 | G15: 24 | H15: Tekrar (kapalı kitap aktif hatırlama, konu başına ~8 dk): The Chemical Context of Life (D+1); Water and Life (D+1); Carbon and Molecular Diversity (D+1) | J15: Not Started
A16: 2026-10-31-08 | B16: 46326 | C16: Cumartesi | D16: CMPE371 | E16: Min | F16: P3 | G16: 8 | H16: Tekrar (kapalı kitap aktif hatırlama, konu başına ~8 dk): Önkoşul: karmaşık sayılar ve Euler (D+1) | J16: Not Started
A17: 2026-11-01-01 | B17: 46327 | C17: Pazar | D17: BIO110 | E17: Min | F17: P1 | G17: 60 | H17: Hücre turu II — mitokondri, kloroplast, sitoiskelet, hücre dışı matriks, hücre bağlantıları. ▸ Organel → görev tablosu + 12 soru | I17: Campbell Biology (ilgili bölüm; baskıya göre numara değişir) + hoca slaytı — Materyal bekleniyor | J17: Not Started
A18: 2026-11-01-02 | B18: 46327 | C18: Pazar | D18: BIO110 | E18: Min | F18: P1 | G18: 80 | H18: Membrane Structure and Function — akışkan mozaik model, seçici geçirgenlik, difüzyon/ozmoz, tonisite, aktif taşıma, kotransport. ▸ Ozmoz/tonisite 6 senaryo + 15 soru | I18: Campbell Biology (ilgili bölüm; baskıya göre numara değişir) + hoca slaytı — Materyal bekleniyor | J18: Not Started
A19: 2026-11-01-03 | B19: 46327 | C19: Pazar | D19: BIO110 | E19: Min | F19: P1 | G19: 80 | H19: An Introduction to Metabolism — enerji, termodinamik, ΔG, ATP döngüsü, enzimler, inhibisyon, regülasyon. ▸ Enzim grafiği yorumlama 5 soru + 15 soru | I19: Campbell Biology (ilgili bölüm; baskıya göre numara değişir) + hoca slaytı — Materyal bekleniyor | J19: Not Started
A20: 2026-11-01-04 | B20: 46327 | C20: Pazar | D20: BIO110 | E20: Min | F20: P1 | G20: 110 | H20: Cellular Respiration — glikoliz, piruvat oksidasyonu, Krebs, ETZ/oksidatif fosforilasyon, fermentasyon; net ATP/NADH hesabı. ▸ Yolu bellekten çiz (girdi/çıktı tablosu) + 20 soru | I20: Campbell Biology (ilgili bölüm; baskıya göre numara değişir) + hoca slaytı — Materyal bekleniyor | J20: Not Started
A21: 2026-11-01-05 | B21: 46327 | C21: Pazar | D21: BIO110 | E21: Ext | F21: P1 | G21: 60 | H21: Konu testi (B01–B08) — karma test. ▸ 40 soru + yanlış analizi | I21: Campbell Biology (ilgili bölüm; baskıya göre numara değişir) + hoca slaytı — Materyal bekleniyor | J21: Not Started
A22: 2026-11-01-06 | B22: 46327 | C22: Pazar | D22: CMPE371 | E22: Ext | F22: P2 | G22: 70 | H22: Introduction to Signals and Systems — sürekli/ayrık sinyal, enerji/güç, zaman kaydırma-ölçekleme-ters çevirme, sistem kavramı. ▸ 8 temel + 5 orta sinyal dönüşüm problemi | I22: Hoca slaytı + ders kitabı (syllabus'ta belirtilmemiş: Materyal bekleniyor) — Materyal bekleniyor | J22: Not Started
A23: 2026-11-01-07 | B23: 46327 | C23: Pazar | D23: CMPE327 | E23: Min | F23: P3 | G23: 8 | H23: Tekrar (kapalı kitap aktif hatırlama, konu başına ~8 dk): DFA (D+1) | J23: Not Started
A24: 2026-11-01-08 | B24: 46327 | C24: Pazar | D24: BIO110 | E24: Min | F24: P2 | G24: 24 | H24: Tekrar (kapalı kitap aktif hatırlama, konu başına ~8 dk): Büyük moleküller I: karbonhidrat + lipid (D+1); Büyük moleküller II: protein + nükleik asit (D+1); Hücre turu I (D+1) | J24: Not Started
A25: 2026-11-01-09 | B25: 46327 | C25: Pazar | D25: CMPE371 | E25: Min | F25: P3 | G25: 8 | H25: Tekrar (kapalı kitap aktif hatırlama, konu başına ~8 dk): Önkoşul: trigonometri, üstel, türev/integral (D+1) | J25: Not Started
A26: 2026-11-02-01 | B26: 46328 | C26: Pazartesi | D26: BIO110 | E26: Min | F26: P1 | G26: 90 | H26: Photosynthesis — ışık reaksiyonları, Calvin döngüsü, C3/C4/CAM, solunumla karşılaştırma. ▸ Kloroplast şeması + solunum–fotosentez karşılaştırma tablosu + 15 soru | I26: Campbell Biology (ilgili bölüm; baskıya göre numara değişir) + hoca slaytı — Materyal bekleniyor | J26: Not Started
A27: 2026-11-02-02 | B27: 46328 | C27: Pazartesi | D27: BIO110 | E27: Min | F27: P1 | G27: 60 | H27: Karma deneme 1 (B01–B09) — tam kapsam deneme. ▸ 50 soru, sınav hızında | I27: Campbell Biology (ilgili bölüm; baskıya göre numara değişir) + hoca slaytı — Materyal bekleniyor | J27: Not Started
A28: 2026-11-02-03 | B28: 46328 | C28: Pazartesi | D28: BIO110 | E28: Min | F28: P1 | G28: 40 | H28: Deneme yanlış analizi — her yanlış için sebep: bilgi/kavram/dikkat. ▸ Yanlış konuları 15'er dk yeniden çalış | I28: Campbell Biology (ilgili bölüm; baskıya göre numara değişir) + hoca slaytı — Materyal bekleniyor | J28: Not Started
A29: 2026-11-02-04 | B29: 46328 | C29: Pazartesi | D29: BIO110 | E29: Ext | F29: P1 | G29: 40 | H29: Şema ve tablo seti — solunum, fotosentez, membran, hücre şemaları. ▸ Boş kağıda 6 şemayı belleğten çiz | I29: Campbell Biology (ilgili bölüm; baskıya göre numara değişir) + hoca slaytı — Materyal bekleniyor | J29: Not Started
A30: 2026-11-02-05 | B30: 46328 | C30: Pazartesi | D30: CMPE371 | E30: Ext | F30: P2 | G30: 70 | H30: Sinusoids — genlik, frekans, faz, periyot, fazör gösterimi, sinüzoid toplamı. ▸ 8 temel + 5 orta problem, yanlış analizi | I30: Hoca slaytı + ders kitabı (syllabus'ta belirtilmemiş: Materyal bekleniyor) — Materyal bekleniyor | J30: Not Started
A31: 2026-11-02-06 | B31: 46328 | C31: Pazartesi | D31: BIO110 | E31: Min | F31: P2 | G31: 56 | H31: Tekrar (kapalı kitap aktif hatırlama, konu başına ~8 dk): Hücre turu II (D+1); Membrane Structure and Function (D+1); An Introduction to Metabolism (D+1); Cellular Respiration (D+1); The Chemical Context of Life (D+3); Water and Life (D+3); Carbon and Molecular Diversity (D+3) | J31: Not Started
A32: 2026-11-02-07 | B32: 46328 | C32: Pazartesi | D32: CMPE371 | E32: Min | F32: P3 | G32: 16 | H32: Tekrar (kapalı kitap aktif hatırlama, konu başına ~8 dk): Introduction to Signals and Systems (D+1); Önkoşul: karmaşık sayılar ve Euler (D+3) | J32: Not Started
A33: 2026-11-02-08 | B33: 46328 | C33: Pazartesi | D33: CMPE327 | E33: Min | F33: P3 | G33: 8 | H33: Tekrar (kapalı kitap aktif hatırlama, konu başına ~8 dk): Central concepts + mathematical preliminaries (D+3) | J33: Not Started
A34: 2026-11-03-01 | B34: 46329 | C34: Salı | D34: BIO110 | E34: Min | F34: P1 | G34: 60 | H34: Son kontrollü tekrar — yalnızca zayıf konular + şemalar, yeni konu yok. ▸ Flashcard son tur, 30 soru karışık | I34: Campbell Biology (ilgili bölüm; baskıya göre numara değişir) + hoca slaytı — Materyal bekleniyor | J34: Not Started
A35: 2026-11-03-02 | B35: 46329 | C35: Salı | D35: BIO110 | E35: Min | F35: P1 | G35: 10 | H35: Sınav günü hazırlığı — Kimlik/öğrenci kartı, kalem, saat, salon; yeni konu YOK. ▸ Gece uykusu önce, sabah 20 dk şema gözden geçirme | J35: Not Started
A36: 2026-11-03-03 | B36: 46329 | C36: Salı | D36: CMPE371 | E36: Ext | F36: P1 | G36: 70 | H36: Special signals — birim basamak, impuls, rampa, üstel, çift/tek, periyodiklik. ▸ 8 temel + 5 orta problem | I36: Hoca slaytı + ders kitabı (syllabus'ta belirtilmemiş: Materyal bekleniyor) — Materyal bekleniyor | J36: Not Started
A37: 2026-11-03-04 | B37: 46329 | C37: Salı | D37: CMPE327 | E37: Ext | F37: P2 | G37: 60 | H37: DFA tasarım pratiği — karma dil kalıpları. ▸ 15 DFA tasarla; her birine 3 test string | I37: Hoca slaytı + ders kitabı (syllabus'ta belirtilmemiş: Materyal bekleniyor) — Materyal bekleniyor | J37: Not Started
A38: 2026-11-03-05 | B38: 46329 | C38: Salı | D38: CMPE421 | E38: Ext | F38: P3 | G38: 60 | H38: Intro to AI + intelligent agents — AI tanımı, PEAS, ortam türleri, ajan türleri. ▸ 6 PEAS tanımı + 10 kavram sorusu | I38: Hoca slaytı (syllabus kitap belirtmiyor: Materyal bekleniyor) — Materyal bekleniyor | J38: Not Started
A39: 2026-11-03-06 | B39: 46329 | C39: Salı | D39: CMPE499 | E39: Ext | F39: P3 | G39: 45 | H39: Rapor: yönerge + içerik planı — bölüm yönergesi/şablon, sayfa sınırı, başlık iskeleti. ▸ İskelet + her başlığa 2 madde | J39: Not Started | L39: ★
A40: 2026-11-03-07 | B40: 46329 | C40: Salı | D40: BIO110 | E40: Min | F40: P2 | G40: 32 | H40: Tekrar (kapalı kitap aktif hatırlama, konu başına ~8 dk): Photosynthesis (D+1); Büyük moleküller I: karbonhidrat + lipid (D+3); Büyük moleküller II: protein + nükleik asit (D+3); Hücre turu I (D+3) | J40: Not Started
...

Sheet Course Progress
A1: Ders bazlı ilerleme (görev tamamlanma — öğrenme seviyesi DEĞİL)
A2: Öğrenme seviyesi için Topic Mastery sayfasına bak. Excel açıldığında TODAY() ile otomatik hesaplanır.
A4: Ders | B4: Toplam görev | C4: Tamamlanan | D4: % Tamamlanma | E4: Min görev | F4: Min tamamlanan | G4: % Min plan | H4: Planlanan dk | I4: Tamamlanan dk | J4: Geciken | K4: In Progress | L4: Postponed | M4: Blocked
A5: BIO110 | B5: =COUNTIFS('Daily Tasks'!$D$2:$D$435,$A5) -> 92 | C5: =COUNTIFS('Daily Tasks'!$D$2:$D$435,$A5,'Daily Tasks'!$J$2:$J$435,"Completed") -> 0 | D5: =IF(B5=0,0,C5/B5) -> 0 | E5: =COUNTIFS('Daily Tasks'!$D$2:$D$435,$A5,'Daily Tasks'!$E$2:$E$435,"Min") -> 62 | F5: =COUNTIFS('Daily Tasks'!$D$2:$D$435,$A5,'Daily Tasks'!$E$2:$E$435,"Min",'Daily Tasks'!$J$2:$J$435,"Completed") -> 0 | G5: =IF(E5=0,0,F5/E5) -> 0 | H5: =SUMIFS('Daily Tasks'!$G$2:$G$435,'Daily Tasks'!$D$2:$D$435,$A5) -> 3815 | I5: =SUMIFS('Daily Tasks'!$G$2:$G$435,'Daily Tasks'!$D$2:$D$435,$A5,'Daily Tasks'!$J$2:$J$435,"Completed") -> 0 | J5: =COUNTIFS('Daily Tasks'!$D$2:$D$435,$A5,'Daily Tasks'!$J$2:$J$435,"<>Completed",'Daily Tasks'!$B$2:$B$435,"<"&TODAY()) | K5: =COUNTIFS('Daily Tasks'!$D$2:$D$435,$A5,'Daily Tasks'!$J$2:$J$435,"In Progress") | L5: =COUNTIFS('Daily Tasks'!$D$2:$D$435,$A5,'Daily Tasks'!$J$2:$J$435,"Postponed") | M5: =COUNTIFS('Daily Tasks'!$D$2:$D$435,$A5,'Daily Tasks'!$J$2:$J$435,"Blocked")
A6: CMPE371 | B6: =COUNTIFS('Daily Tasks'!$D$2:$D$435,$A6) -> 85 | C6: =COUNTIFS('Daily Tasks'!$D$2:$D$435,$A6,'Daily Tasks'!$J$2:$J$435,"Completed") -> 0 | D6: =IF(B6=0,0,C6/B6) -> 0 | E6: =COUNTIFS('Daily Tasks'!$D$2:$D$435,$A6,'Daily Tasks'!$E$2:$E$435,"Min") -> 47 | F6: =COUNTIFS('Daily Tasks'!$D$2:$D$435,$A6,'Daily Tasks'!$E$2:$E$435,"Min",'Daily Tasks'!$J$2:$J$435,"Completed") -> 0 | G6: =IF(E6=0,0,F6/E6) -> 0 | H6: =SUMIFS('Daily Tasks'!$G$2:$G$435,'Daily Tasks'!$D$2:$D$435,$A6) -> 3224 | I6: =SUMIFS('Daily Tasks'!$G$2:$G$435,'Daily Tasks'!$D$2:$D$435,$A6,'Daily Tasks'!$J$2:$J$435,"Completed") -> 0 | J6: =COUNTIFS('Daily Tasks'!$D$2:$D$435,$A6,'Daily Tasks'!$J$2:$J$435,"<>Completed",'Daily Tasks'!$B$2:$B$435,"<"&TODAY()) | K6: =COUNTIFS('Daily Tasks'!$D$2:$D$435,$A6,'Daily Tasks'!$J$2:$J$435,"In Progress") | L6: =COUNTIFS('Daily Tasks'!$D$2:$D$435,$A6,'Daily Tasks'!$J$2:$J$435,"Postponed") | M6: =COUNTIFS('Daily Tasks'!$D$2:$D$435,$A6,'Daily Tasks'!$J$2:$J$435,"Blocked")
A7: CMPE327 | B7: =COUNTIFS('Daily Tasks'!$D$2:$D$435,$A7) -> 91 | C7: =COUNTIFS('Daily Tasks'!$D$2:$D$435,$A7,'Daily Tasks'!$J$2:$J$435,"Completed") -> 0 | D7: =IF(B7=0,0,C7/B7) -> 0 | E7: =COUNTIFS('Daily Tasks'!$D$2:$D$435,$A7,'Daily Tasks'!$E$2:$E$435,"Min") -> 54 | F7: =COUNTIFS('Daily Tasks'!$D$2:$D$435,$A7,'Daily Tasks'!$E$2:$E$435,"Min",'Daily Tasks'!$J$2:$J$435,"Completed") -> 0 | G7: =IF(E7=0,0,F7/E7) -> 0 | H7: =SUMIFS('Daily Tasks'!$G$2:$G$435,'Daily Tasks'!$D$2:$D$435,$A7) -> 2946 | I7: =SUMIFS('Daily Tasks'!$G$2:$G$435,'Daily Tasks'!$D$2:$D$435,$A7,'Daily Tasks'!$J$2:$J$435,"Completed") -> 0 | J7: =COUNTIFS('Daily Tasks'!$D$2:$D$435,$A7,'Daily Tasks'!$J$2:$J$435,"<>Completed",'Daily Tasks'!$B$2:$B$435,"<"&TODAY()) | K7: =COUNTIFS('Daily Tasks'!$D$2:$D$435,$A7,'Daily Tasks'!$J$2:$J$435,"In Progress") | L7: =COUNTIFS('Daily Tasks'!$D$2:$D$435,$A7,'Daily Tasks'!$J$2:$J$435,"Postponed") | M7: =COUNTIFS('Daily Tasks'!$D$2:$D$435,$A7,'Daily Tasks'!$J$2:$J$435,"Blocked")
A8: CMPE421 | B8: =COUNTIFS('Daily Tasks'!$D$2:$D$435,$A8) -> 77 | C8: =COUNTIFS('Daily Tasks'!$D$2:$D$435,$A8,'Daily Tasks'!$J$2:$J$435,"Completed") -> 0 | D8: =IF(B8=0,0,C8/B8) -> 0 | E8: =COUNTIFS('Daily Tasks'!$D$2:$D$435,$A8,'Daily Tasks'!$E$2:$E$435,"Min") -> 44 | F8: =COUNTIFS('Daily Tasks'!$D$2:$D$435,$A8,'Daily Tasks'!$E$2:$E$435,"Min",'Daily Tasks'!$J$2:$J$435,"Completed") -> 0 | G8: =IF(E8=0,0,F8/E8) -> 0 | H8: =SUMIFS('Daily Tasks'!$G$2:$G$435,'Daily Tasks'!$D$2:$D$435,$A8) -> 2510 | I8: =SUMIFS('Daily Tasks'!$G$2:$G$435,'Daily Tasks'!$D$2:$D$435,$A8,'Daily Tasks'!$J$2:$J$435,"Completed") -> 0 | J8: =COUNTIFS('Daily Tasks'!$D$2:$D$435,$A8,'Daily Tasks'!$J$2:$J$435,"<>Completed",'Daily Tasks'!$B$2:$B$435,"<"&TODAY()) | K8: =COUNTIFS('Daily Tasks'!$D$2:$D$435,$A8,'Daily Tasks'!$J$2:$J$435,"In Progress") | L8: =COUNTIFS('Daily Tasks'!$D$2:$D$435,$A8,'Daily Tasks'!$J$2:$J$435,"Postponed") | M8: =COUNTIFS('Daily Tasks'!$D$2:$D$435,$A8,'Daily Tasks'!$J$2:$J$435,"Blocked")
A9: CMPE453 | B9: =COUNTIFS('Daily Tasks'!$D$2:$D$435,$A9) -> 68 | C9: =COUNTIFS('Daily Tasks'!$D$2:$D$435,$A9,'Daily Tasks'!$J$2:$J$435,"Completed") -> 0 | D9: =IF(B9=0,0,C9/B9) -> 0 | E9: =COUNTIFS('Daily Tasks'!$D$2:$D$435,$A9,'Daily Tasks'!$E$2:$E$435,"Min") -> 42 | F9: =COUNTIFS('Daily Tasks'!$D$2:$D$435,$A9,'Daily Tasks'!$E$2:$E$435,"Min",'Daily Tasks'!$J$2:$J$435,"Completed") -> 0 | G9: =IF(E9=0,0,F9/E9) -> 0 | H9: =SUMIFS('Daily Tasks'!$G$2:$G$435,'Daily Tasks'!$D$2:$D$435,$A9) -> 2171 | I9: =SUMIFS('Daily Tasks'!$G$2:$G$435,'Daily Tasks'!$D$2:$D$435,$A9,'Daily Tasks'!$J$2:$J$435,"Completed") -> 0 | J9: =COUNTIFS('Daily Tasks'!$D$2:$D$435,$A9,'Daily Tasks'!$J$2:$J$435,"<>Completed",'Daily Tasks'!$B$2:$B$435,"<"&TODAY()) | K9: =COUNTIFS('Daily Tasks'!$D$2:$D$435,$A9,'Daily Tasks'!$J$2:$J$435,"In Progress") | L9: =COUNTIFS('Daily Tasks'!$D$2:$D$435,$A9,'Daily Tasks'!$J$2:$J$435,"Postponed") | M9: =COUNTIFS('Daily Tasks'!$D$2:$D$435,$A9,'Daily Tasks'!$J$2:$J$435,"Blocked")
A10: CMPE499 | B10: =COUNTIFS('Daily Tasks'!$D$2:$D$435,$A10) -> 18 | C10: =COUNTIFS('Daily Tasks'!$D$2:$D$435,$A10,'Daily Tasks'!$J$2:$J$435,"Completed") -> 0 | D10: =IF(B10=0,0,C10/B10) -> 0 | E10: =COUNTIFS('Daily Tasks'!$D$2:$D$435,$A10,'Daily Tasks'!$E$2:$E$435,"Min") -> 11 | F10: =COUNTIFS('Daily Tasks'!$D$2:$D$435,$A10,'Daily Tasks'!$E$2:$E$435,"Min",'Daily Tasks'!$J$2:$J$435,"Completed") -> 0 | G10: =IF(E10=0,0,F10/E10) -> 0 | H10: =SUMIFS('Daily Tasks'!$G$2:$G$435,'Daily Tasks'!$D$2:$D$435,$A10) -> 905 | I10: =SUMIFS('Daily Tasks'!$G$2:$G$435,'Daily Tasks'!$D$2:$D$435,$A10,'Daily Tasks'!$J$2:$J$435,"Completed") -> 0 | J10: =COUNTIFS('Daily Tasks'!$D$2:$D$435,$A10,'Daily Tasks'!$J$2:$J$435,"<>Completed",'Daily Tasks'!$B$2:$B$435,"<"&TODAY()) | K10: =COUNTIFS('Daily Tasks'!$D$2:$D$435,$A10,'Daily Tasks'!$J$2:$J$435,"In Progress") | L10: =COUNTIFS('Daily Tasks'!$D$2:$D$435,$A10,'Daily Tasks'!$J$2:$J$435,"Postponed") | M10: =COUNTIFS('Daily Tasks'!$D$2:$D$435,$A10,'Daily Tasks'!$J$2:$J$435,"Blocked")
A11: TOPLAM | B11: =SUM(B5:B10) | C11: =SUM(C5:C10) | D11: =IF(B11=0,0,C11/B11) | E11: =SUM(E5:E10) | F11: =SUM(F5:F10) | G11: =IF(E11=0,0,F11/E11) | H11: =SUM(H5:H10) | I11: =SUM(I5:I10) | J11: =SUM(J5:J10) | K11: =SUM(K5:K10) | L11: =SUM(L5:L10) | M11: =SUM(M5:M10)

Sheet Topic Mastery
A1: Konu öğrenme seviyesi (kendi test sonucunla doldur — sarı alanlar)
A2: %85–100 Güçlü · %70–84 İyi ama tekrar gerekli · %50–69 Eksik · %0–49 Önkoşul + konu yeniden. Başlangıç çalışma politikasıdır, başarı garantisi değildir.
A4: Ders | B4: Konu / Blok | C4: İlk öğrenme | D4: Son tekrar | E4: Öğrenme skoru % | F4: Seviye | G4: Notlar
A5: BIO110 | B5: B01 · The Chemical Context of Life | C5: 46325 | F5: =IF(E5="","",IF(E5>=0.85,"Güçlü",IF(E5>=0.7,"İyi — tekrar gerekli",IF(E5>=0.5,"Eksik","Yeniden çalış"))))
A6: BIO110 | B6: B02 · Water and Life | C6: 46325 | F6: =IF(E6="","",IF(E6>=0.85,"Güçlü",IF(E6>=0.7,"İyi — tekrar gerekli",IF(E6>=0.5,"Eksik","Yeniden çalış"))))
A7: BIO110 | B7: B03 · Carbon and Molecular Diversity | C7: 46325 | F7: =IF(E7="","",IF(E7>=0.85,"Güçlü",IF(E7>=0.7,"İyi — tekrar gerekli",IF(E7>=0.5,"Eksik","Yeniden çalış"))))
A8: BIO110 | B8: B04a · Büyük moleküller I: karbonhidrat + lipid | C8: 46326 | F8: =IF(E8="","",IF(E8>=0.85,"Güçlü",IF(E8>=0.7,"İyi — tekrar gerekli",IF(E8>=0.5,"Eksik","Yeniden çalış"))))
A9: BIO110 | B9: B04b · Büyük moleküller II: protein + nükleik asit | C9: 46326 | F9: =IF(E9="","",IF(E9>=0.85,"Güçlü",IF(E9>=0.7,"İyi — tekrar gerekli",IF(E9>=0.5,"Eksik","Yeniden çalış"))))
A10: BIO110 | B10: B05a · Hücre turu I | C10: 46326 | F10: =IF(E10="","",IF(E10>=0.85,"Güçlü",IF(E10>=0.7,"İyi — tekrar gerekli",IF(E10>=0.5,"Eksik","Yeniden çalış"))))
A11: BIO110 | B11: B05b · Hücre turu II | C11: 46327 | F11: =IF(E11="","",IF(E11>=0.85,"Güçlü",IF(E11>=0.7,"İyi — tekrar gerekli",IF(E11>=0.5,"Eksik","Yeniden çalış"))))
A12: BIO110 | B12: B06 · Membrane Structure and Function | C12: 46327 | F12: =IF(E12="","",IF(E12>=0.85,"Güçlü",IF(E12>=0.7,"İyi — tekrar gerekli",IF(E12>=0.5,"Eksik","Yeniden çalış"))))
A13: BIO110 | B13: B07 · An Introduction to Metabolism | C13: 46327 | F13: =IF(E13="","",IF(E13>=0.85,"Güçlü",IF(E13>=0.7,"İyi — tekrar gerekli",IF(E13>=0.5,"Eksik","Yeniden çalış"))))
A14: BIO110 | B14: B08 · Cellular Respiration | C14: 46327 | F14: =IF(E14="","",IF(E14>=0.85,"Güçlü",IF(E14>=0.7,"İyi — tekrar gerekli",IF(E14>=0.5,"Eksik","Yeniden çalış"))))
A15: BIO110 | B15: B09 · Photosynthesis | C15: 46328 | F15: =IF(E15="","",IF(E15>=0.85,"Güçlü",IF(E15>=0.7,"İyi — tekrar gerekli",IF(E15>=0.5,"Eksik","Yeniden çalış"))))
A16: BIO110 | B16: B10 · The Cell Cycle and Cellular Reproduction | C16: 46339 | F16: =IF(E16="","",IF(E16>=0.85,"Güçlü",IF(E16>=0.7,"İyi — tekrar gerekli",IF(E16>=0.5,"Eksik","Yeniden çalış"))))
... A87: CMPE453 | B87: M13 · PWM for ARM Cortex | C87: 46366 | F87: =IF(E87="","",IF(E87>=0.85,"Güçlü",IF(E87>=0.7,"İyi — tekrar gerekli",IF(E87>=0.5,"Eksik","Yeniden çalış"))))

Sheet Exam Countdown
A1: Sınav ve teslim geri sayımı
A2: Teyit Bekliyor = doğrulanmamış tarih. Kesin tarih öğrenince sarı hücreleri düzenle. Excel açıldığında TODAY() ile otomatik hesaplanır.
A4: Ders | B4: Başlık | C4: Tarih | D4: Bitiş | E4: Saat | F4: Durum | G4: Gün kaldı | H4: Not
A5: BIO110 | B5: BIO110 Midterm 1 | C5: 46329 | E5: belli değil | F5: Kullanıcı teyitli | G5: =IF(C5="","",C5-TODAY()) | H5: Kullanıcı teyitli: 3 Kasım (syllabus satırı 5/6 Kas'ı gösteriyor ama kullanıcının tarihi esas). Kapsam B01–B09 varsayımı; saat belli değil.
A6: CMPE371 | B6: CMPE371 HW1 (2–6 Kas haftası) | C6: 46332 | E6: belli değil | F6: Teyit Bekliyor | G6: =IF(C6="","",C6-TODAY()) | H6: Syllabus W6: HW 1. Tam teslim günü yok; en erken Cuma varsayıldı.
A7: CMPE453 | B7: CMPE453 Midterm | C7: 46338 | E7: 18:00–20:00 | F7: Kesin (syllabus) | G7: =IF(C7="","",C7-TODAY()) | H7: Syllabus'ta 12 Kasım 18:00–20:00 yazıyor. Ağırlık syllabus'ta yok (30 varsayım). Kapsam W1–W7 varsayımı.
A8: CMPE327 | B8: CMPE327 Midterm (15 Kasım) | C8: 46341 | E8: belli değil | F8: Kullanıcı teyitli | G8: =IF(C8="","",C8-TODAY()) | H8: Kullanıcı teyitli (el yazısı 15.11.2026, Pazar). Syllabus W8 (16–20 Kas) ile farklı; saat belli değil. Kapsam W1–W8 varsayımı.
A9: CMPE421 | B9: CMPE421 Midterm (20 Kasım) | C9: 46346 | E9: belli değil | F9: Kullanıcı teyitli | G9: =IF(C9="","",C9-TODAY()) | H9: Kullanıcı teyitli (el yazısı 20 November). Saat belli değil. Kapsam W1–W9 varsayımı.
A10: CMPE499 | B10: CMPE499 Summer Training Report (STR) | C10: 46348 | E10: belli değil | F10: Kesin (syllabus) | G10: =IF(C10="","",C10-TODAY()) | H10: Syllabus: Due Nov 22, 2026 (Pazar). Saat belli değil. Plan: 20 Kasım'da yükle.
A11: CMPE371 | B11: CMPE371 Midterm (23–27 Kas haftası) | C11: 46349 | D11: 46353 | E11: belli değil | F11: Teyit Bekliyor | G11: =IF(C11="","",C11-TODAY()) | H11: Syllabus W9: Midterm Exam. Gün/saat belli değil.
A12: BIO110 | B12: BIO110 Midterm 2 (26/27 Kas) | C12: 46352 | D12: 46353 | E12: belli değil | F12: Teyit Bekliyor | G12: =IF(C12="","",C12-TODAY()) | H12: Syllabus: 26/27.11 Second Midterm Review and Exam. Gün/saat belli değil.
A13: CMPE499 | B13: CMPE499 Summer Training Video | C13: 46355 | E13: belli değil | F13: Kesin (syllabus) | G13: =IF(C13="","",C13-TODAY()) | H13: Syllabus: Due Nov 29, 2026 (Pazar). Saat belli değil. Plan: 26 Kasım'da yükle.
A14: CMPE371 | B14: CMPE371 Quiz 1 (7–11 Ara haftası) | C14: 46363 | D14: 46367 | E14: belli değil | F14: Teyit Bekliyor | G14: =IF(C14="","",C14-TODAY()) | H14: Syllabus W11: Quiz 1 ('Quiz 1 will be in Week 11').
A15: BIO110 | B15: BIO110 Proje sunumları (10–31 Ara) | C15: 46366 | D15: 46387 | E15: belli değil | F15: Teyit Bekliyor (aralık) | G15: =IF(C15="","",C15-TODAY()) | H15: Syllabus: 10/11.12 – 31.12 Project Presentations. Bireysel 15–20 slayt. Sıra/gün belli değil; 9 Aralık'a hazır ol.
A16: CMPE327 | B16: CMPE327 Quiz-2 (14–18 Ara haftası) | C16: 46370 | D16: 46374 | E16: belli değil | F16: Teyit Bekliyor | G16: =IF(C16="","",C16-TODAY()) | H16: Syllabus W12: Quiz-2.
A17: GENEL | B17: Final sınavları (W14 sonrası) | E17: belli değil | F17: Duyurulacak | G17: =IF(C17="","",C17-TODAY()) | H17: Tarihler duyurulacak. Kesin tarih UYDURULMADI; plan 31 Aralık'a kadar kümülatif tekrarla biter.

Sheet Assignments
A1: Ödev / teslim / quiz takibi
A3: Ders | B3: Teslim / Ödev | C3: Resmi son tarih | D3: İç hedef | E3: Durum | F3: Gün kaldı | G3: Not
A4: CMPE499 | B4: Evaluation Form | C4: 46302 | E4: Completed | F4: =IF(C4="","",C4-TODAY()) | G4: Kullanıcı: teslim edildi.
A5: CMPE499 | B5: Summer Training Report (STR) | C5: 46348 | D5: 46346 | E5: Not Started | F5: =IF(C5="","",C5-TODAY()) | G5: Resmi son: Pazar. Plan: 2 gün erken yükle.
A6: CMPE499 | B6: Summer Training Video | C6: 46355 | D6: 46351 | E6: Not Started | F6: =IF(C6="","",C6-TODAY()) | G6: Resmi son: Pazar. Plan: 3 gün erken yükle.
A7: CMPE371 | B7: HW 1 (Teyit Bekliyor) | C7: 46332 | D7: 46334 | E7: Not Started | F7: =IF(C7="","",C7-TODAY()) | G7: Syllabus W6 (2–6 Kas). Kesin gün yok; Cuma varsayıldı.
A8: CMPE371 | B8: Quiz 1 (Teyit Bekliyor) | C8: 46363 | D8: 46359 | E8: Not Started | F8: =IF(C8="","",C8-TODAY()) | G8: Syllabus W11 (7–11 Ara).
A9: CMPE327 | B9: Quiz-2 (Teyit Bekliyor) | C9: 46370 | D9: 46363 | E9: Not Started | F9: =IF(C9="","",C9-TODAY()) | G9: Syllabus W12 (14–18 Ara).
A10: BIO110 | B10: Proje sunumu (15–20 slayt) | C10: 46366 | D10: 46361 | E10: Not Started | F10: =IF(C10="","",C10-TODAY()) | G10: Sunum penceresi 10–31 Ara; sıra belli değil.
A11: CMPE327 | B11: Midterm (kullanıcı teyitli) | C11: 46341 | D11: 46340 | E11: Not Started | F11: =IF(C11="","",C11-TODAY()) | G11: El yazısı 15.11.2026 (Pazar); saat belli değil.
A12: CMPE421 | B12: Midterm (kullanıcı teyitli) | C12: 46346 | D12: 46344 | E12: Not Started | F12: =IF(C12="","",C12-TODAY()) | G12: El yazısı 20 Kasım; saat belli değil.
A13: CMPE421 | B13: Homework(lar) %30 | D13: 46361 | E13: Not Started | F13: =IF(C13="","",C13-TODAY()) | G13: Teslim tarihi/sayısı syllabus'ta yok — doğrula.

Sheet Revision Schedule
A1: Aralıklı tekrar takvimi (D+1, D+3, D+7, D+14)
A2: Sınav yaklaşınca sıkıştır; iyi öğrenilen konuda azalt (Topic Mastery). Günlük görevlerdeki 'Tekrar' satırları aynı kaynaktan üretilir.
A4: Ders | B4: Konu / Blok | C4: Öğrenme | D4: D+1 | E4: D+3 | F4: D+7 | G4: D+14 | H4: D+1 ✓ | I4: D+3 ✓ | J4: D+7 ✓ | K4: D+14 ✓
A5: BIO110 | B5: B01 · The Chemical Context of Life | C5: 46325 | D5: 46326 | E5: 46328 | F5: 46332 | G5: 46339 | H5: Pending | I5: Pending | J5: Pending | K5: Pending
A6: BIO110 | B6: B02 · Water and Life | C6: 46325 | D6: 46326 | E6: 46328 | F6: 46332 | G6: 46339 | H6: Pending | I6: Pending | J6: Pending | K6: Pending
A7: BIO110 | B7: B03 · Carbon and Molecular Diversity | C7: 46325 | D7: 46326 | E7: 46328 | F7: 46332 | G7: 46339 | H7: Pending | I7: Pending | J7: Pending | K7: Pending
A8: BIO110 | B8: B04a · Büyük moleküller I: karbonhidrat + lipid | C8: 46326 | D8: 46327 | E8: 46329 | F8: 46333 | G8: 46340 | H8: Pending | I8: Pending | J8: Pending | K8: Pending
A9: BIO110 | B9: B04b · Büyük moleküller II: protein + nükleik asit | C9: 46326 | D9: 46327 | E9: 46329 | F9: 46333 | G9: 46340 | H9: Pending | I9: Pending | J9: Pending | K9: Pending
A10: BIO110 | B10: B05a · Hücre turu I | C10: 46326 | D10: 46327 | E10: 46329 | F10: 46333 | G10: 46340 | H10: Pending | I10: Pending | J10: Pending | K10: Pending
A11: BIO110 | B11: B05b · Hücre turu II | C11: 46327 | D11: 46328 | E11: 46330 | F11: 46334 | G11: 46341 | H11: Pending | I11: Pending | J11: Pending | K11: Pending
A12: BIO110 | B12: B06 · Membrane Structure and Function | C12: 46327 | D12: 46328 | E12: 46330 | F12: 46334 | G12: 46341 | H12: Pending | I12: Pending | J12: Pending | K12: Pending
A13: BIO110 | B13: B07 · An Introduction to Metabolism | C13: 46327 | D13: 46328 | E13: 46330 | F13: 46334 | G13: 46341 | H13: Pending | I13: Pending | J13: Pending | K13: Pending
A14: BIO110 | B14: B08 · Cellular Respiration | C14: 46327 | D14: 46328 | E14: 46330 | F14: 46334 | G14: 46341 | H14: Pending | I14: Pending | J14: Pending | K14: Pending
A15: BIO110 | B15: B09 · Photosynthesis | C15: 46328 | D15: 46329 | E15: 46331 | F15: 46335 | G15: 46342 | H15: Pending | I15: Pending | J15: Pending | K15: Pending
A16: BIO110 | B16: B10 · The Cell Cycle and Cellular Reproduction | C16: 46339 | D16: 46340 | E16: 46342 | F16: 46346 | G16: 46353 | H16: Pending | I16: Pending | J16: Pending | K16: Pending
... A87: CMPE453 | B87: M13 · PWM for ARM Cortex | C87: 46366 | D87: 46367 | E87: 46369 | F87: 46373 | G87: 46380 | H87: Pending | I87: Pending | J87: Pending | K87: Pending

Sheet Mistake Log
A1: Yanlış defteri — her yanlışın SEBEBİNİ yaz; aynı hata tekrarlanıyorsa o konuya düzeltici çalışma ekle
A3: Tarih | B3: Ders | C3: Konu | D3: Kaynak / soru | E3: Hata türü | F3: Ne yanlış gitti | G3: Doğru çözüm / kural | H3: Tekrar (D+3) | I3: Tekrar (D+7) | J3: Düzeltildi?
H4: =IF($A4="","",$A4+3) | I4: =IF($A4="","",$A4+7)
H5: =IF($A5="","",$A5+3) | I5: =IF($A5="","",$A5+7)
H6: =IF($A6="","",$A6+3) | I6: =IF($A6="","",$A6+7)
H7: =IF($A7="","",$A7+3) | I7: =IF($A7="","",$A7+7)
H8: =IF($A8="","",$A8+3) | I8: =IF($A8="","",$A8+7)
H9: =IF($A9="","",$A9+3) | I9: =IF($A9="","",$A9+7)
H10: =IF($A10="","",$A10+3) | I10: =IF($A10="","",$A10+7)
H11: =IF($A11="","",$A11+3) | I11: =IF($A11="","",$A11+7)
H12: =IF($A12="","",$A12+3) | I12: =IF($A12="","",$A12+7)
H13: =IF($A13="","",$A13+3) | I13: =IF($A13="","",$A13+7)
H14: =IF($A14="","",$A14+3) | I14: =IF($A14="","",$A14+7)
H15: =IF($A15="","",$A15+3) | I15: =IF($A15="","",$A15+7)
... H303: =IF($A303="","",$A303+3) | I303: =IF($A303="","",$A303+7)

Sheet Slide Coverage
A1: SLIDE_COVERAGE_MATRIX — slayt/dosya kapsama matrisi
A2: Hiç slayt/PDF paylaşılmadı → tüm satırlar 'Materyal bekleniyor'. Dosyalar gelince Dosya ve Sayfa aralığı sütunlarını doldur; hiçbir sayfa/içerik UYDURULMADI.
A4: Ders | B4: Dosya | C4: Sayfa/slayt aralığı | D4: Syllabus konusu | E4: Zorluk (1–5) | F4: Tahmini dk | G4: Öğrenme çıktısı (uygulama) | H4: Çalışma tarihi | I4: Tekrar tarihi (D+1) | J4: Durum
A5: BIO110 | B5: Materyal bekleniyor | C5: — | D5: Chemical Context of Life | E5: 3 | F5: 75 | G5: 15 kavram sorusu + 10 flashcard (bağ türleri tablosu) | H5: 46325 | I5: 46326 | J5: Not Started
A6: BIO110 | B6: Materyal bekleniyor | C6: — | D6: Water and Life | E6: 3 | F6: 70 | G6: 15 kavram sorusu + özellik→örnek tablosu + 10 flashcard | H6: 46325 | I6: 46326 | J6: Not Started
A7: BIO110 | B7: Materyal bekleniyor | C7: — | D7: Carbon and the Molecular Diversity of Life | E7: 3 | F7: 60 | G7: Fonksiyonel grup kartları (7) + 12 izomer/grup sorusu | H7: 46325 | I7: 46326 | J7: Not Started
A8: BIO110 | B8: Materyal bekleniyor | C8: — | D8: Large Biological Molecules (carbs, lipids) | E8: 3 | F8: 70 | G8: Karşılaştırma tablosu + 15 soru | H8: 46326 | I8: 46327 | J8: Not Started
A9: BIO110 | B9: Materyal bekleniyor | C9: — | D9: Large Biological Molecules (proteins, nucleic acids) | E9: 3 | F9: 80 | G9: Protein yapı basamaklarını belleğten çiz + 15 soru | H9: 46326 | I9: 46327 | J9: Not Started
A10: BIO110 | B10: Materyal bekleniyor | C10: — | D10: A Tour of the Cell (1) | E10: 3 | F10: 70 | G10: Hücre şemasını boş çizip etiketle + 15 soru | H10: 46326 | I10: 46327 | J10: Not Started
A11: BIO110 | B11: Materyal bekleniyor | C11: — | D11: A Tour of the Cell (2) | E11: 3 | F11: 60 | G11: Organel → görev tablosu + 12 soru | H11: 46327 | I11: 46328 | J11: Not Started
A12: BIO110 | B12: Materyal bekleniyor | C12: — | D12: Membrane Structure and Function | E12: 3 | F12: 80 | G12: Ozmoz/tonisite 6 senaryo + 15 soru | H12: 46327 | I12: 46328 | J12: Not Started
A13: BIO110 | B13: Materyal bekleniyor | C13: — | D13: An Introduction to Metabolism | E13: 3 | F13: 80 | G13: Enzim grafiği yorumlama 5 soru + 15 soru | H13: 46327 | I13: 46328 | J13: Not Started
A14: BIO110 | B14: Materyal bekleniyor | C14: — | D14: Cellular Respiration | E14: 3 | F14: 110 | G14: Yolu bellekten çiz (girdi/çıktı tablosu) + 20 soru | H14: 46327 | I14: 46328 | J14: Not Started
A15: BIO110 | B15: Materyal bekleniyor | C15: — | D15: Photosynthesis | E15: 3 | F15: 90 | G15: Kloroplast şeması + solunum–fotosentez karşılaştırma tablosu + 15 soru | H15: 46328 | I15: 46329 | J15: Not Started
A16: BIO110 | B16: Materyal bekleniyor | C16: — | D16: Cell Cycle and Cellular Reproduction | E16: 3 | F16: 80 | G16: Mitoz evreleri çizimi + 15 soru | H16: 46339 | I16: 46340 | J16: Not Started
... A87: CMPE453 | B87: Materyal bekleniyor | C87: — | D87: PWM for ARM Cortex | E87: 4 | F87: 80 | G87: 5 hesap + 2 kod (Lab 6) | H87: 46366 | I87: 46367 | J87: Not Started

Sheet Weekly Reviews
A1: Haftalık değerlendirme
A3: Hafta | B3: Başlangıç | C3: Bitiş | D3: Planlanan görev | E3: Tamamlanan | F3: % Tamamlanma | G3: Planlanan dk | H3: Tamamlanan dk | I3: Eksik kalan konular | J3: Sonraki hafta hedefleri | K3: Notlar
A4: Hafta 5 (kalan) | B4: 46325 | C4: 46327 | D4: =COUNTIFS('Daily Tasks'!$B$2:$B$435,">="&$B4,'Daily Tasks'!$B$2:$B$435,"<="&$C4) | E4: =COUNTIFS('Daily Tasks'!$B$2:$B$435,">="&$B4,'Daily Tasks'!$B$2:$B$435,"<="&$C4,'Daily Tasks'!$J$2:$J$435,"Completed") | F4: =IF(D4=0,0,E4/D4) | G4: =SUMIFS('Daily Tasks'!$G$2:$G$435,'Daily Tasks'!$B$2:$B$435,">="&$B4,'Daily Tasks'!$B$2:$B$435,"<="&$C4) | H4: =SUMIFS('Daily Tasks'!$G$2:$G$435,'Daily Tasks'!$B$2:$B$435,">="&$B4,'Daily Tasks'!$B$2:$B$435,"<="&$C4,'Daily Tasks'!$J$2:$J$435,"Completed")
A5: Hafta 6 | B5: 46328 | C5: 46334 | D5: =COUNTIFS('Daily Tasks'!$B$2:$B$435,">="&$B5,'Daily Tasks'!$B$2:$B$435,"<="&$C5) | E5: =COUNTIFS('Daily Tasks'!$B$2:$B$435,">="&$B5,'Daily Tasks'!$B$2:$B$435,"<="&$C5,'Daily Tasks'!$J$2:$J$435,"Completed") | F5: =IF(D5=0,0,E5/D5) | G5: =SUMIFS('Daily Tasks'!$G$2:$G$435,'Daily Tasks'!$B$2:$B$435,">="&$B5,'Daily Tasks'!$B$2:$B$435,"<="&$C5) | H5: =SUMIFS('Daily Tasks'!$G$2:$G$435,'Daily Tasks'!$B$2:$B$435,">="&$B5,'Daily Tasks'!$B$2:$B$435,"<="&$C5,'Daily Tasks'!$J$2:$J$435,"Completed")
A6: Hafta 7 | B6: 46335 | C6: 46341 | D6: =COUNTIFS('Daily Tasks'!$B$2:$B$435,">="&$B6,'Daily Tasks'!$B$2:$B$435,"<="&$C6) | E6: =COUNTIFS('Daily Tasks'!$B$2:$B$435,">="&$B6,'Daily Tasks'!$B$2:$B$435,"<="&$C6,'Daily Tasks'!$J$2:$J$435,"Completed") | F6: =IF(D6=0,0,E6/D6) | G6: =SUMIFS('Daily Tasks'!$G$2:$G$435,'Daily Tasks'!$B$2:$B$435,">="&$B6,'Daily Tasks'!$B$2:$B$435,"<="&$C6) | H6: =SUMIFS('Daily Tasks'!$G$2:$G$435,'Daily Tasks'!$B$2:$B$435,">="&$B6,'Daily Tasks'!$B$2:$B$435,"<="&$C6,'Daily Tasks'!$J$2:$J$435,"Completed")
A7: Hafta 8 | B7: 46342 | C7: 46348 | D7: =COUNTIFS('Daily Tasks'!$B$2:$B$435,">="&$B7,'Daily Tasks'!$B$2:$B$435,"<="&$C7) | E7: =COUNTIFS('Daily Tasks'!$B$2:$B$435,">="&$B7,'Daily Tasks'!$B$2:$B$435,"<="&$C7,'Daily Tasks'!$J$2:$J$435,"Completed") | F7: =IF(D7=0,0,E7/D7) | G7: =SUMIFS('Daily Tasks'!$G$2:$G$435,'Daily Tasks'!$B$2:$B$435,">="&$B7,'Daily Tasks'!$B$2:$B$435,"<="&$C7) | H7: =SUMIFS('Daily Tasks'!$G$2:$G$435,'Daily Tasks'!$B$2:$B$435,">="&$B7,'Daily Tasks'!$B$2:$B$435,"<="&$C7,'Daily Tasks'!$J$2:$J$435,"Completed")
A8: Hafta 9 | B8: 46349 | C8: 46355 | D8: =COUNTIFS('Daily Tasks'!$B$2:$B$435,">="&$B8,'Daily Tasks'!$B$2:$B$435,"<="&$C8) | E8: =COUNTIFS('Daily Tasks'!$B$2:$B$435,">="&$B8,'Daily Tasks'!$B$2:$B$435,"<="&$C8,'Daily Tasks'!$J$2:$J$435,"Completed") | F8: =IF(D8=0,0,E8/D8) | G8: =SUMIFS('Daily Tasks'!$G$2:$G$435,'Daily Tasks'!$B$2:$B$435,">="&$B8,'Daily Tasks'!$B$2:$B$435,"<="&$C8) | H8: =SUMIFS('Daily Tasks'!$G$2:$G$435,'Daily Tasks'!$B$2:$B$435,">="&$B8,'Daily Tasks'!$B$2:$B$435,"<="&$C8,'Daily Tasks'!$J$2:$J$435,"Completed")
A9: Hafta 10 | B9: 46356 | C9: 46362 | D9: =COUNTIFS('Daily Tasks'!$B$2:$B$435,">="&$B9,'Daily Tasks'!$B$2:$B$435,"<="&$C9) | E9: =COUNTIFS('Daily Tasks'!$B$2:$B$435,">="&$B9,'Daily Tasks'!$B$2:$B$435,"<="&$C9,'Daily Tasks'!$J$2:$J$435,"Completed") | F9: =IF(D9=0,0,E9/D9) | G9: =SUMIFS('Daily Tasks'!$G$2:$G$435,'Daily Tasks'!$B$2:$B$435,">="&$B9,'Daily Tasks'!$B$2:$B$435,"<="&$C9) | H9: =SUMIFS('Daily Tasks'!$G$2:$G$435,'Daily Tasks'!$B$2:$B$435,">="&$B9,'Daily Tasks'!$B$2:$B$435,"<="&$C9,'Daily Tasks'!$J$2:$J$435,"Completed")
A10: Hafta 11 | B10: 46363 | C10: 46369 | D10: =COUNTIFS('Daily Tasks'!$B$2:$B$435,">="&$B10,'Daily Tasks'!$B$2:$B$435,"<="&$C10) | E10: =COUNTIFS('Daily Tasks'!$B$2:$B$435,">="&$B10,'Daily Tasks'!$B$2:$B$435,"<="&$C10,'Daily Tasks'!$J$2:$J$435,"Completed") | F10: =IF(D10=0,0,E10/D10) | G10: =SUMIFS('Daily Tasks'!$G$2:$G$435,'Daily Tasks'!$B$2:$B$435,">="&$B10,'Daily Tasks'!$B$2:$B$435,"<="&$C10) | H10: =SUMIFS('Daily Tasks'!$G$2:$G$435,'Daily Tasks'!$B$2:$B$435,">="&$B10,'Daily Tasks'!$B$2:$B$435,"<="&$C10,'Daily Tasks'!$J$2:$J$435,"Completed")
A11: Hafta 12 | B11: 46370 | C11: 46376 | D11: =COUNTIFS('Daily Tasks'!$B$2:$B$435,">="&$B11,'Daily Tasks'!$B$2:$B$435,"<="&$C11) | E11: =COUNTIFS('Daily Tasks'!$B$2:$B$435,">="&$B11,'Daily Tasks'!$B$2:$B$435,"<="&$C11,'Daily Tasks'!$J$2:$J$435,"Completed") | F11: =IF(D11=0,0,E11/D11) | G11: =SUMIFS('Daily Tasks'!$G$2:$G$435,'Daily Tasks'!$B$2:$B$435,">="&$B11,'Daily Tasks'!$B$2:$B$435,"<="&$C11) | H11: =SUMIFS('Daily Tasks'!$G$2:$G$435,'Daily Tasks'!$B$2:$B$435,">="&$B11,'Daily Tasks'!$B$2:$B$435,"<="&$C11,'Daily Tasks'!$J$2:$J$435,"Completed")
A12: Hafta 13 | B12: 46377 | C12: 46383 | D12: =COUNTIFS('Daily Tasks'!$B$2:$B$435,">="&$B12,'Daily Tasks'!$B$2:$B$435,"<="&$C12) | E12: =COUNTIFS('Daily Tasks'!$B$2:$B$435,">="&$B12,'Daily Tasks'!$B$2:$B$435,"<="&$C12,'Daily Tasks'!$J$2:$J$435,"Completed") | F12: =IF(D12=0,0,E12/D12) | G12: =SUMIFS('Daily Tasks'!$G$2:$G$435,'Daily Tasks'!$B$2:$B$435,">="&$B12,'Daily Tasks'!$B$2:$B$435,"<="&$C12) | H12: =SUMIFS('Daily Tasks'!$G$2:$G$435,'Daily Tasks'!$B$2:$B$435,">="&$B12,'Daily Tasks'!$B$2:$B$435,"<="&$C12,'Daily Tasks'!$J$2:$J$435,"Completed")
A13: Hafta 14 | B13: 46384 | C13: 46387 | D13: =COUNTIFS('Daily Tasks'!$B$2:$B$435,">="&$B13,'Daily Tasks'!$B$2:$B$435,"<="&$C13) | E13: =COUNTIFS('Daily Tasks'!$B$2:$B$435,">="&$B13,'Daily Tasks'!$B$2:$B$435,"<="&$C13,'Daily Tasks'!$J$2:$J$435,"Completed") | F13: =IF(D13=0,0,E13/D13) | G13: =SUMIFS('Daily Tasks'!$G$2:$G$435,'Daily Tasks'!$B$2:$B$435,">="&$B13,'Daily Tasks'!$B$2:$B$435,"<="&$C13) | H13: =SUMIFS('Daily Tasks'!$G$2:$G$435,'Daily Tasks'!$B$2:$B$435,">="&$B13,'Daily Tasks'!$B$2:$B$435,"<="&$C13,'Daily Tasks'!$J$2:$J$435,"Completed")
